Workbook

Sheet Drivers
B2: X | C2: ="Financial Statement Model for "&D5 -> Financial Statement Model for StandardAero
C3: $ in thousands except per share | N3: Comments
C5: Company name | D5: StandardAero
C6: Ticker | D6: SARO
C7: Latest closing share price | D7: 25.59
C8: Latest closing share price date | D8: 46119
C9: Latest fiscal year end date | D9: 46022
C10: Shares outstanding (millions) | D10: 334294 | N10: Outstanding at Dec 31, 2025 per 10-K BS. Jan 2026 repurchase of 1,637k shares (subsequent event) reduces to 332,657k.
C11: Case | D11: Description | F11: Source
C12: 2 | D12: =OFFSET(D12,$C$12,) -> [Case 2] | F12: =OFFSET(F12,$C$12,) -> Investment Case
C13: 1 | D13: [Case 1] | F13: Management Case
C14: 2 | D14: [Case 2] | F14: Investment Case
C15: 3 | D15: [Case 3] | F15: Downside Projection
C17: Growth rates & margins
C18: Fiscal year | E18: 2023 | F18: 2024 | G18: 2025 | H18: 2026 | I18: 2027 | J18: 2028 | K18: 2029 | L18: 2030
C19: Fiscal year end date | E19: 45291 | F19: 45657 | G19: 46022 | H19: 46387 | I19: 46752 | J19: 47118 | K19: 47483 | L19: 47848
C21: Revenue growth | F21: =(Model!F9-Model!E9)/Model!E9 -> 0.14767369 | G21: =(Model!H9-Model!F9)/Model!F9 -> 0.15759512 | H21: =(Model!I9-Model!H9)/Model!H9 -> 0.12467503 | I21: =(Model!J9-Model!I9)/Model!I9 -> 0.13607751 | J21: =(Model!K9-Model!J9)/Model!J9 -> 0.12136802 | K21: =(Model!L9-Model!K9)/Model!K9 -> 0.1120143 | L21: =(Model!M9-Model!L9)/Model!L9 -> 0.094108201 | N21: LEAP/CFM56 shop visits ramping; ~80% of revenue under long-term agreements; aging installed base drives MRO demand through 2030; military spending elevated due to geopolitical tensions; business aviation fleet growth
C23: Engine Service growth rate | F23: =OFFSET(F23,Drivers!$C$12,) -> 0.14688652 | G23: =OFFSET(G23,Drivers!$C$12,) -> 0.15269168 | H23: =OFFSET(H23,Drivers!$C$12,) -> 0.12 | I23: =OFFSET(I23,Drivers!$C$12,) -> 0.13 | J23: =OFFSET(J23,Drivers!$C$12,) -> 0.11 | K23: =OFFSET(K23,Drivers!$C$12,) -> 0.1 | L23: =OFFSET(L23,Drivers!$C$12,) -> 0.08
C24: =Drivers!$C$13 -> 1 | D24: =Drivers!$D$13 -> [Case 1] | F24: =(Model!F$6-Model!E$6)/Model!E$6 -> 0.14688652 | G24: =(Model!H$6-Model!F$6)/Model!F$6 -> 0.15269168 | H24: 0.145 | I24: 0.125 | J24: 0.115 | K24: 0.105 | L24: 0.1
C25: =Drivers!$C$14 -> 2 | D25: =Drivers!$D$14 -> [Case 2] | F25: =(Model!F$6-Model!E$6)/Model!E$6 -> 0.14688652 | G25: =(Model!H$6-Model!F$6)/Model!F$6 -> 0.15269168 | H25: 0.12 | I25: 0.13 | J25: 0.11 | K25: 0.1 | L25: 0.08 | N25: Haircut by 2–3pts Because supply chain parts availability risk and LEAP ramp execution uncertainty are flagged as key risks in the 10-K Item 1A.
C26: =Drivers!$C$15 -> 3 | D26: =Drivers!$D$15 -> [Case 3] | F26: =(Model!F$6-Model!E$6)/Model!E$6 -> 0.14688652 | G26: =(Model!H$6-Model!F$6)/Model!F$6 -> 0.15269168 | H26: 0.09 | I26: 0.09 | J26: 0.08 | K26: 0.08 | L26: 0.07 | N26: LEAP ramp delay costs 3pts in Year 1–2. By Year 4 gap narrows as backlog eventually clears.
C28: Component Repair Service growth rate | F28: =OFFSET(F28,Drivers!$C$12,) -> 0.15388301 | G28: =OFFSET(G28,Drivers!$C$12,) -> 0.19603931 | H28: =OFFSET(H28,Drivers!$C$12,) -> 0.16 | I28: =OFFSET(I28,Drivers!$C$12,) -> 0.15 | J28: =OFFSET(J28,Drivers!$C$12,) -> 0.15 | K28: =OFFSET(K28,Drivers!$C$12,) -> 0.14 | L28: =OFFSET(L28,Drivers!$C$12,) -> 0.13
C29: =Drivers!$C$13 -> 1 | D29: =Drivers!$D$13 -> [Case 1] | F29: =(Model!F$7-Model!E$7)/Model!E$7 -> 0.15388301 | G29: =(Model!H$7-Model!F$7)/Model!F$7 -> 0.19603931 | H29: 0.17 | I29: 0.16 | J29: 0.155 | K29: 0.155 | L29: 0.15
C30: =Drivers!$C$14 -> 2 | D30: =Drivers!$D$14 -> [Case 2] | F30: =(Model!F$7-Model!E$7)/Model!E$7 -> 0.15388301 | G30: =(Model!H$7-Model!F$7)/Model!F$7 -> 0.19603931 | H30: 0.16 | I30: 0.15 | J30: 0.15 | K30: 0.14 | L30: 0.13 | N30: Component Repair has been the faster-growing segment (19.6% growth in 2025) driven by Aero Turbine and military demand. But 28.6% Adj EBITDA margins can't expand forever, and the military helicopter market is cyclical.
C31: =Drivers!$C$15 -> 3 | D31: =Drivers!$D$15 -> [Case 3] | F31: =(Model!F$7-Model!E$7)/Model!E$7 -> 0.15388301 | G31: =(Model!H$7-Model!F$7)/Model!F$7 -> 0.19603931 | H31: 0.15 | I31: 0.15 | J31: 0.14 | K31: 0.14 | L31: 0.13 | N31: Phoenix fire + gov shutdown persists through H2 2026. Military budget pressure from potential defense cuts limits recovery.
C33: Gross profit margin | E33: =OFFSET(E33,Drivers!$C$12,) -> 0.13922408 | F33: =OFFSET(F33,Drivers!$C$12,) -> 0.14399825 | G33: =OFFSET(G33,Drivers!$C$12,) -> 0.14803303 | H33: =OFFSET(H33,Drivers!$C$12,) -> 0.148 | I33: =OFFSET(I33,Drivers!$C$12,) -> 0.15 | J33: =OFFSET(J33,Drivers!$C$12,) -> 0.152 | K33: =OFFSET(K33,Drivers!$C$12,) -> 0.153 | L33: =OFFSET(L33,Drivers!$C$12,) -> 0.154
C34: =Drivers!$C$13 -> 1 | D34: =Drivers!$D$13 -> [Case 1] | E34: =Model!E$11/Model!E$9 -> 0.13922408 | F34: =Model!F$11/Model!F$9 -> 0.14399825 | G34: =Model!H$11/Model!H$9 -> 0.14803303 | H34: 0.152 | I34: 0.155 | J34: 0.16 | K34: 0.163 | L34: 0.165 | N34: LEAP learning curve progressively reduces industrialization costs; mix shift toward higher-margin Component Repair Services; operating leverage on fixed overhead as volumes scale; partially offset by material cost inflation pass-through
C35: =Drivers!$C$14 -> 2 | D35: =Drivers!$D$14 -> [Case 2] | E35: =Model!E$11/Model!E$9 -> 0.13922408 | F35: =Model!F$11/Model!F$9 -> 0.14399825 | G35: =Model!H$11/Model!H$9 -> 0.14803303 | H35: 0.148 | I35: 0.15 | J35: 0.152 | K35: 0.153 | L35: 0.154 | N35: Materials are 71.5% of COGS, and tariff risk remains live even after the IEEPA ruling was struck down. LEAP industrialization savings are real but partially offset by inflationary labor pressures. The 10-K explicitly says "timing delays may impact margins" on tariff pass-throughs.
C36: =Drivers!$C$15 -> 3 | D36: =Drivers!$D$15 -> [Case 3] | E36: =Model!E$11/Model!E$9 -> 0.13922408 | F36: =Model!F$11/Model!F$9 -> 0.14399825 | G36: =Model!H$11/Model!H$9 -> 0.14803303 | H36: 0.143 | I36: 0.145 | J36: 0.146 | K36: 0.148 | L36: 0.15 | N36: 50bps GP compression from OEM inflation.
C38: SG&A % of sales | E38: =OFFSET(E38,Drivers!$C$12,) -> 0.044434228 | F38: =OFFSET(F38,Drivers!$C$12,) -> 0.048517126 | G38: =OFFSET(G38,Drivers!$C$12,) -> 0.040858146 | H38: =OFFSET(H38,Drivers!$C$12,) -> 0.041 | I38: =OFFSET(I38,Drivers!$C$12,) -> 0.04 | J38: =OFFSET(J38,Drivers!$C$12,) -> 0.04 | K38: =OFFSET(K38,Drivers!$C$12,) -> 0.039 | L38: =OFFSET(L38,Drivers!$C$12,) -> 0.039
C39: =Drivers!$C$13 -> 1 | D39: =Drivers!$D$13 -> [Case 1] | E39: =-Model!E$13/Model!E$9 -> 0.044434228 | F39: =-Model!F$13/Model!F$9 -> 0.048517126 | G39: =-Model!H$13/Model!H$9 -> 0.040858146 | H39: 0.041 | I39: 0.04 | J39: 0.039 | K39: 0.038 | L39: 0.037 | N39: SG&A already declined to 4.1% in 2025 (from 4.9% in 2024). Post-IPO one-time costs are behind the company. Further leverage expected as revenue scales against relatively fixed corporate overhead and sales force
C40: =Drivers!$C$14 -> 2 | D40: =Drivers!$D$14 -> [Case 2] | E40: =-Model!E$13/Model!E$9 -> 0.044434228 | F40: =-Model!F$13/Model!F$9 -> 0.048517126 | G40: =-Model!H$13/Model!H$9 -> 0.040858146 | H40: 0.041 | I40: 0.04 | J40: 0.04 | K40: 0.039 | L40: 0.039 | N40: The 10-K notes material weaknesses in internal controls requiring additional personnel and compliance investment. Remediation costs will partially offset the operating leverage from revenue growth.
C41: =Drivers!$C$15 -> 3 | D41: =Drivers!$D$15 -> [Case 3] | E41: =-Model!E$13/Model!E$9 -> 0.044434228 | F41: =-Model!F$13/Model!F$9 -> 0.048517126 | G41: =-Model!H$13/Model!H$9 -> 0.040858146 | H41: 0.043 | I41: 0.041 | J41: 0.041 | K41: 0.04 | L41: 0.04 | N41: 20bps SG&A increase from material weakness remediation costs (10-K disclosed).
C43: Tax rate | E43: =OFFSET(E43,Drivers!$C$12,) -> 7.8491893 | F43: =OFFSET(F43,Drivers!$C$12,) -> 0.86577296 | G43: =OFFSET(G43,Drivers!$C$12,) -> 0.2638576 | H43: =OFFSET(H43,Drivers!$C$12,) -> 0.3 | I43: =OFFSET(I43,Drivers!$C$12,) -> 0.3 | J43: =OFFSET(J43,Drivers!$C$12,) -> 0.3 | K43: =OFFSET(K43,Drivers!$C$12,) -> 0.3 | L43: =OFFSET(L43,Drivers!$C$12,) -> 0.3
C44: =Drivers!$C$13 -> 1 | D44: =Drivers!$D$13 -> [Case 1] | E44: =-Model!E$23/Model!E$22 -> 7.8491893 | F44: =-Model!F$23/Model!F$22 -> 0.86577296 | G44: =-Model!H$23/Model!H$22 -> 0.2638576 | H44: 0.3 | I44: 0.3 | J44: 0.3 | K44: 0.3 | L44: 0.3 | N44: 2025 effective rate of 26.4% includes GILTI, state taxes (California heavy), and changes in uncertain tax benefits. OBBBA provisions (signed Jul 4, 2025) restore favorable business tax treatment in 2026–2027 rate likely drifts toward 24–26% as Canada/foreign mix optimizes and interest carryforwards begin to release
C45: =Drivers!$C$14 -> 2 | D45: =Drivers!$D$14 -> [Case 2] | E45: =-Model!E$23/Model!E$22 -> 7.8491893 | F45: =-Model!F$23/Model!F$22 -> 0.86577296 | G45: =-Model!H$23/Model!H$22 -> 0.2638576 | H45: 0.3 | I45: 0.3 | J45: 0.3 | K45: 0.3 | L45: 0.3 | N45: The OBBBA provisions are recent and their permanence is uncertain
C46: =Drivers!$C$15 -> 3 | D46: =Drivers!$D$15 -> [Case 3] | E46: =-Model!E$23/Model!E$22 -> 7.8491893 | F46: =-Model!F$23/Model!F$22 -> 0.86577296 | G46: =-Model!H$23/Model!H$22 -> 0.2638576 | H46: 0.3 | I46: 0.3 | J46: 0.3 | K46: 0.3 | L46: 0.3
C48: Adjusted EBITDA Margin | E48: =OFFSET(E48,Drivers!$C$12,) -> 0.12295969 | F48: =OFFSET(F48,Drivers!$C$12,) -> 0.13185257 | G48: =OFFSET(G48,Drivers!$C$12,) -> 0.13330648 | H48: =OFFSET(H48,Drivers!$C$12,) -> 0.13 | I48: =OFFSET(I48,Drivers!$C$12,) -> 0.135 | J48: =OFFSET(J48,Drivers!$C$12,) -> 0.14 | K48: =OFFSET(K48,Drivers!$C$12,) -> 0.143 | L48: =OFFSET(L48,Drivers!$C$12,) -> 0.146
C49: =Drivers!$C$13 -> 1 | D49: =Drivers!$D$13 -> [Case 1] | E49: =Model!E$37/Model!E$9 -> 0.12295969 | F49: =Model!F$37/Model!F$9 -> 0.13185257 | G49: =Model!H$37/Model!H$9 -> 0.13330648 | H49: 0.139 | I49: 0.143 | J49: 0.147 | K49: 0.15 | L49: 0.153
C50: =Drivers!$C$14 -> 2 | D50: =Drivers!$D$14 -> [Case 2] | E50: =Model!E$37/Model!E$9 -> 0.12295969 | F50: =Model!F$37/Model!F$9 -> 0.13185257 | G50: =Model!H$37/Model!H$9 -> 0.13330648 | H50: 0.13 | I50: 0.135 | J50: 0.14 | K50: 0.143 | L50: 0.146 | N50: Business transformation costs ($26M in 2025) won't go to zero as the company is still ramping LEAP and may need ongoing industrialization investment.
...

Sheet Model
B2: X | C2: INCOME STATEMENT
C3: Fiscal year | E3: =F3-1 -> 2023 | F3: =H3-1 -> 2024 | H3: =YEAR(Drivers!D9) -> 2025 | I3: =H3+1 -> 2026 | J3: =I3+1 -> 2027 | K3: =J3+1 -> 2028 | L3: =K3+1 -> 2029 | M3: =L3+1 -> 2030
C4: Fiscal year end date | E4: =EOMONTH(F4,-12) -> 45291 | F4: =EOMONTH(H4,-12) -> 45657 | H4: =Drivers!D9 -> 46022 | I4: =EOMONTH(H4,12) -> 46387 | J4: =EOMONTH(I4,12) -> 46752 | K4: =EOMONTH(J4,12) -> 47118 | L4: =EOMONTH(K4,12) -> 47483 | M4: =EOMONTH(L4,12) -> 47848 | O4: Comments
C6: Revenue from Engine Repair | E6: 4049868 | F6: 4644739 | H6: 5353952 | I6: =H6*(1+Drivers!H23) -> 5996426.2 | J6: =I6*(1+Drivers!I23) -> 6775961.7 | K6: =J6*(1+Drivers!J23) -> 7521317.4 | L6: =K6*(1+Drivers!K23) -> 8273449.2 | M6: =L6*(1+Drivers!L23) -> 8935325.1
C7: Revenue from Component Repair | E7: 513416 | F7: 592422 | H7: 708560 | I7: =H7*(1+Drivers!H28) -> 821929.6 | J7: =I7*(1+Drivers!I28) -> 945219.04 | K7: =J7*(1+Drivers!J28) -> 1087001.9 | L7: =K7*(1+Drivers!K28) -> 1239182.2 | M7: =L7*(1+Drivers!L28) -> 1400275.8
C8: Revenue from M&A | E8: 0 | F8: 0 | H8: 0 | I8: =I260 -> 0 | J8: =J260 -> 25000 | K8: =K260 -> 78000 | L8: =L260 -> 146680 | M8: =M260 -> 232730.8
C9: Total Revenue | E9: =SUM(E6:E8) -> 4563284 | F9: =SUM(F6:F8) -> 5237161 | G9: =SUM(G6:G8) -> 0 | H9: =SUM(H6:H8) -> 6062512 | I9: =SUM(I6:I8) -> 6818355.8 | J9: =SUM(J6:J8) -> 7746180.7 | K9: =SUM(K6:K8) -> 8686319.3 | L9: =SUM(L6:L8) -> 9659311.3 | M9: =SUM(M6:M8) -> 10568332
C10: Cost of sales | E10: -3927965 | F10: -4483019 | H10: -5165060 | I10: =I11-I9 -> -5809239.2 | J10: =J11-J9 -> -6584253.6 | K10: =K11-K9 -> -7365998.8 | L10: =L11-L9 -> -8181436.7 | M10: =M11-M9 -> -8940808.7
C11: Gross Profit | E11: =SUM(E9:E10) -> 635319 | F11: =SUM(F9:F10) -> 754142 | H11: =SUM(H9:H10) -> 897452 | I11: =I9*Drivers!H33 -> 1009116.7 | J11: =J9*Drivers!I33 -> 1161927.1 | K11: =K9*Drivers!J33 -> 1320320.5 | L11: =L9*Drivers!K33 -> 1477874.6 | M11: =M9*Drivers!L33 -> 1627523.1
C12: Amortisation of intangible assets | E12: -93681 | F12: -95457 | H12: -98681 | I12: =-I127*0.7516 -> -91261.527 | J12: =-J127*0.7516 -> -83538.837 | K12: =-K127*0.7516 -> -82367.092 | L12: =-L127*0.7516 -> -79979.259 | M12: =-M127*0.7516 -> -79200.602 | O12: Formula: Total Amortization from intangible Assets acc to note 9× 75% to excludes OEM auth amort which goes through COGS per Note 9.
C13: Selling, general & administrative | E13: -202766 | F13: -254092 | H13: -247703 | I13: =-I9*Drivers!H38 -> -279552.59 | J13: =-J9*Drivers!I38 -> -309847.23 | K13: =-K9*Drivers!J38 -> -347452.77 | L13: =-L9*Drivers!K38 -> -376713.14 | M13: =-M9*Drivers!L38 -> -412164.94
C14: Acquisition Cost | E14: -1514 | F14: -1374 | H14: 0 | I14: =H14 -> 0 | J14: =I14 -> 0 | K14: =J14 -> 0 | L14: =K14 -> 0 | M14: =L14 -> 0
C15: Operating profit (EBIT) | E15: =SUM(E11:E14) -> 337358 | F15: =SUM(F11:F14) -> 403219 | H15: =SUM(H11:H14) -> 551068 | I15: =SUM(I11:I14) -> 638302.55 | J15: =SUM(J11:J14) -> 768541.04 | K15: =SUM(K11:K14) -> 890500.67 | L15: =SUM(L11:L14) -> 1021182.2 | M15: =SUM(M11:M14) -> 1136157.5
C16: Interest income | E16: 0 | F16: 0 | H16: 0 | I16: =I172 -> 0 | J16: =J172 -> 0 | K16: =K172 -> 0 | L16: =L172 -> 0 | M16: =M172 -> 0
C17: Interest expense | E17: -309645 | F17: -282507 | H17: -174217 | I17: =I159 -> -427448.47 | J17: =J159 -> -421783.23 | K17: =K159 -> -413288.21 | L17: =L159 -> -400676.56 | M17: =M159 -> -385353.39
C18: Amotisation of Financing fees | E18: 0 | F18: 0 | H18: 0 | I18: =-I231 -> -17340.423 | J18: =-J231 -> -17340.423 | K18: =-K231 -> -17340.423 | L18: =-L231 -> -17340.423 | M18: =-M231 -> -17340.423
C19: Refinancing costs | E19: -19921 | F19: -23700 | H19: 0 | I19: =H19 -> 0 | J19: =I19 -> 0 | K19: =J19 -> 0 | L19: =K19 -> 0 | M19: =L19 -> 0
C20: Loss on debt extinguishment | E20: -6182 | F20: -15255 | H20: 0 | I20: =H20 -> 0 | J20: =I20 -> 0 | K20: =J20 -> 0 | L20: =K20 -> 0 | M20: =L20 -> 0
C21: Other expense, net | E21: 3509 | F21: 0 | H21: 0 | I21: 0 | J21: 0 | K21: 0 | L21: 0 | M21: 0
C22: Pretax profit | E22: =SUM(E15:E21) -> 5119 | F22: =SUM(F15:F21) -> 81757 | H22: =SUM(H15:H21) -> 376851 | I22: =SUM(I15:I21) -> 193513.65 | J22: =SUM(J15:J21) -> 329417.39 | K22: =SUM(K15:K21) -> 459872.04 | L22: =SUM(L15:L21) -> 603165.25 | M22: =SUM(M15:M21) -> 733463.73
C23: Taxes | E23: -40180 | F23: -70783 | H23: -99435 | I23: =-I22*Drivers!H43 -> -58054.096 | J23: =-J22*Drivers!I43 -> -98825.217 | K23: =-K22*Drivers!J43 -> -137961.61 | L23: =-L22*Drivers!K43 -> -180949.57 | M23: =-M22*Drivers!L43 -> -220039.12
C24: Net income | E24: =SUM(E22:E23) -> -35061 | F24: =SUM(F22:F23) -> 10974 | H24: =SUM(H22:H23) -> 277416 | I24: =SUM(I22:I23) -> 135459.56 | J24: =SUM(J22:J23) -> 230592.17 | K24: =SUM(K22:K23) -> 321910.43 | L24: =SUM(L22:L23) -> 422215.67 | M24: =SUM(M22:M23) -> 513424.61
C25: Depreciation & amortization | E25: 197104 | F25: 188164 | H25: 193664 | I25: =I129 -> 191602.72 | J25: =J129 -> 190877.6 | K25: =K129 -> 198995.23 | L25: =L129 -> 205833 | M25: =M129 -> 214153.34
C26: EBITDA | E26: =E15+E25 -> 534462 | F26: =F15+F25 -> 591383 | H26: =H15+H25 -> 744732 | I26: =I15+I25 -> 829905.27 | J26: =J15+J25 -> 959418.64 | K26: =K15+K25 -> 1089495.9 | L26: =L15+L25 -> 1227015.2 | M26: =M15+M25 -> 1350310.9
C27: % of Revenue | E27: =E26/E9 -> 0.11712223 | F27: =F26/F9 -> 0.11292053 | G27: =IFERROR(G26/G9,"") | H27: =H26/H9 -> 0.12284215 | I27: =I26/I9 -> 0.12171633 | J27: =J26/J9 -> 0.12385699 | K27: =K26/K9 -> 0.12542665 | L27: =L26/L9 -> 0.12702927 | M27: =M26/M9 -> 0.12776954
C28: Stock based compensation | E28: - | F28: 17376 | H28: 13237 | I28: =0.2%*I9 -> 13636.712 | J28: =0.2%*J9 -> 15492.361 | K28: =0.2%*K9 -> 17372.639 | L28: =0.2%*L9 -> 19318.623 | M28: =0.2%*M9 -> 21136.664
C29: Business transformation costs | E29: - | F29: 43239 | H29: 26028 | I29: - | J29: - | K29: - | L29: - | M29: -
C30: IPO related cost | E30: - | F30: 26909 | H30: 0 | I30: - | J30: - | K30: - | L30: - | M30: -
C31: Integration costs and severance | E31: - | F31: 2782 | H31: 5601 | I31: - | J31: - | K31: - | L31: - | M31: -
C32: Acquisition costs | E32: - | F32: 1374 | H32: 0 | I32: - | J32: - | K32: - | L32: - | M32: -
C33: Insurance recovery | E33: - | F33: 0 | H33: -3000 | I33: - | J33: - | K33: - | L33: - | M33: -
C34: Loss on disposals | E34: - | F34: 0 | H34: 2764 | I34: - | J34: - | K34: - | L34: - | M34: -
C35: Secondary offering costs | E35: - | F35: 0 | H35: 4990 | I35: - | J35: - | K35: - | L35: - | M35: -
C36: Other | E36: - | F36: 7470 | H36: 13820 | I36: - | J36: - | K36: - | L36: - | M36: -
C37: Adj EBITDA | E37: 561100 | F37: =SUM(F26:F36) -> 690533.11 | H37: =SUM(H26:H36) -> 808172.12 | I37: =(I6+I7)*Drivers!H48+I268-I271 -> 886386.26 | J37: =(J6+J7)*Drivers!I48+J268-J271 -> 1042776.1 | K37: =(K6+K7)*Drivers!J48+K268-K271 -> 1212648 | L37: =(L6+L7)*Drivers!K48+L268-L271 -> 1376424.9 | M37: =(M6+M7)*Drivers!L48+M268-M271 -> 1537582.4 | O37: Formula: EBITDA*Adj. EBITDA margin + M&A acquired EBITDA - synergy cost/year
B39: X | C39: BALANCE SHEET
C40: =C3 -> Fiscal year | E40: =E3 -> 2023 | F40: =F3 -> 2024 | G40: =H3 -> 2025 | H40: Pro forma 2025A | I40: =I3 -> 2026 | J40: =J3 -> 2027 | K40: =K3 -> 2028 | L40: =L3 -> 2029 | M40: =M3 -> 2030
C41: =C4 -> Fiscal year end date | E41: =E4 -> 45291 | F41: =F4 -> 45657 | G41: =H4 -> 46022 | H41: =Drivers!D9 -> 46022 | I41: =I4 -> 46387 | J41: =J4 -> 46752 | K41: =K4 -> 47118 | L41: =L4 -> 47483 | M41: =M4 -> 47848
C42: ASSETS
C43: Current Assets
...

Sheet Sources & Uses
B2: X | C2: Sources and Uses | J2: Purchase price
C3: Minimum Equity | E3: 0.4 | J3: Adjusted 2025 Cash EBITDA | L3: =Model!H37 -> 808172.12
C4: Available debt package at closing | E4: =SUM(F7:F9) -> 5253118.8 | J4: Purchase Multiple | L4: 14.5
C6: Sources | E6: EBITDA turns | F6: Amount | J6: TEV | L6: =L4*L3 -> 11718496
C7: Revolver | F7: 0
C8: Bank Debt (Term Loan B) | E8: =D74 -> 4.5 | F8: =E8*L3 -> 3636774.6 | J8: Total Debt to be refi | L8: =Model!G70+Model!G68 -> 2214605
C9: Subordinated Debt | E9: =MIN(D75,D76-E8) -> 2 | F9: =E9*L3 -> 1616344.2
C10: Total Debt | E10: =F10/L3 -> 6.5 | F10: =SUM(F7:F9) -> 5253118.8 | J10: Unrestricted cash | L10: =L11 -> 289717
C11: % Total Sources | F11: =F10/F17 -> 0.42536566 | J11: Cash | L11: =Model!G44 -> 289717
C12: Cash on balance sheet | F12: =L10 -> 289717 | J12: Equity | L12: =L6-L8+L10 -> 9793607.8
C14: Sponsor Equity | E14: =F14/L3 -> 8.422486 | F14: =F17-F10-F12-F13 -> 6806818.4 | G14: =F14/SUM(F13:F14) -> 1
C15: % Total Sources | F15: =F14/F17 -> 0.55117482
C17: Total sources | E17: =F17/L3 -> 15.28097 | F17: =SUM(F24) -> 12349654
C19: Uses | F19: Amount
C20: Purchase of Equity | F20: =L12 -> 9793607.8
C21: Repayment of existing debt | F21: =L8 -> 2214605
C22: Fees (Financing and transaction) | F22: =G31+E34 -> 241441.42
C23: Cash on balance sheet | F23: =-Model!I144 -> 100000
C24: Total uses | F24: =SUM(F20:F23) -> 12349654
B26: X | C26: Fees
C27: Financing | D27: Funded | E27: EBITDA turns | F27: Fees rate | G27: Fees | H27: Term | I27: Fee amount/year
C28: Revolver | D28: =F7 -> 0 | E28: 0 | F28: 0.02 | G28: =D73*L3*0.005 -> 4040.8606 | H28: =G73 -> 5 | I28: =G28/H28 -> 808.17212
C29: Bank Debt (Term Loan B) | D29: =F8 -> 3636774.6 | E29: =E8 -> 4.5 | F29: =1-F74+0.0225 -> 0.0275 | G29: =D29*F29 -> 100011.3 | H29: =G74 -> 7 | I29: =G29/H29 -> 14287.329
C30: Subordinated Debt | D30: =F9 -> 1616344.2 | E30: =E9 -> 2 | F30: 0.0125 | G30: =D30*F30 -> 20204.303 | H30: =G75 -> 9 | I30: =G30/H30 -> 2244.9226
C31: Financing fees | G31: =SUM(G28:G30) -> 124256.46 | I31: =SUM(I28:I30) -> 17340.423
D33: % of offer value | E33: Fee
C34: Trans. fees | D34: 0.01 | E34: =D34*L6 -> 117184.96
C35: Equity % check | D35: =F15 -> 0.55117482
B36: X | C36: IRR Calculation
C37: =Model!C91 -> Fiscal year | H37: =Model!H3 -> 2025 | I37: =Model!I3 -> 2026 | J37: =Model!J3 -> 2027 | K37: =Model!K3 -> 2028 | L37: =Model!L3 -> 2029 | M37: =Model!M3 -> 2030
C38: =Model!C92 -> Fiscal year end date | H38: =Drivers!D9 -> 46022 | I38: =Model!I4 -> 46387 | J38: =Model!J4 -> 46752 | K38: =Model!K4 -> 47118 | L38: =Model!L4 -> 47483 | M38: =Model!M4 -> 47848
C40: Sponsor Equity Invested | H40: =-'Sources & Uses'!F14 -> -6806818.4 | I40: 0 | J40: 0 | K40: 0 | L40: 0 | M40: 0
C41: Dividends Pay | H41: 0 | I41: 0 | J41: 0 | K41: 0 | L41: 0 | M41: 0
C42: Sponsor Equity Value at exit | H42: 0 | I42: 0 | J42: 0 | K42: 0 | L42: 0 | M42: =M50 -> 16533438
C43: Total equity Flows | H43: =SUM(H40:H42) -> -6806818.4 | I43: =SUM(I40:I42) -> 0 | J43: =SUM(J40:J42) -> 0 | K43: =SUM(K40:K42) -> 0 | L43: =SUM(L40:L42) -> 0 | M43: =SUM(M40:M42) -> 16533438
C45: Management Option Pool | D45: 0.08 | M45: =D45*M49 -> 1437690.2
C47: Exit Value | D47: =Model!F191 -> 14.5 | M47: =D47*Model!M185 -> 22294944
C48: Net debt at exit | M48: =-(Model!M70+Model!M68)+Model!M44 -> -4323816.4
C49: Equity value | M49: =SUM(M47,M48) -> 17971128
C50: Sponsor Equity | D50: =1-D45 -> 0.92 | M50: =D50*M49 -> 16533438
...

Sheet vF
B2: X | C2: ="Financial Statement Model for "&D5 -> Financial Statement Model for StandardAero
C3: $ in thousands except per share
C5: Company name | D5: StandardAero
C6: Ticker | D6: SARO
C7: Latest closing share price | D7: 25.59
C8: Latest closing share price date | D8: 46119
C9: Latest fiscal year end date | D9: 46022
C10: Shares outstanding (millions) | D10: 334294 | N10: Outstanding at Dec 31, 2025 per 10-K BS. Jan 2026 repurchase of 1,637k shares (subsequent event) reduces to 332,657k.
C11: Case | D11: Description | F11: Source
C12: 1 | D12: =OFFSET(D12,$C$12,) -> [Case 1] | F12: =OFFSET(F12,$C$12,) -> Management Case
C13: 1 | D13: [Case 1] | F13: Management Case
C14: 2 | D14: [Case 2] | F14: Investment Case
C15: 3 | D15: [Case 3] | F15: Downside Projection
B17: X | C17: INCOME STATEMENT
C18: Fiscal year | E18: =F18-1 -> 2023 | F18: =G18-1 -> 2024 | G18: =YEAR(D9) -> 2025 | H18: =G18+1 -> 2026 | I18: =H18+1 -> 2027 | J18: =I18+1 -> 2028 | K18: =J18+1 -> 2029 | L18: =K18+1 -> 2030
C19: Fiscal year end date | E19: =EOMONTH(F19,-12) -> 45291 | F19: =EOMONTH(G19,-12) -> 45657 | G19: =D9 -> 46022 | H19: =EOMONTH(G19,12) -> 46387 | I19: =EOMONTH(H19,12) -> 46752 | J19: =EOMONTH(I19,12) -> 47118 | K19: =EOMONTH(J19,12) -> 47483 | L19: =EOMONTH(K19,12) -> 47848 | N19: Comments
C21: Revenue from Engine Repair | E21: 4049868 | F21: 4644739 | G21: 5353952 | H21: =G21*(1+H55) -> 6130275 | I21: =H21*(1+I55) -> 6896559.4 | J21: =I21*(1+J55) -> 7689663.8 | K21: =J21*(1+K55) -> 8497078.4 | L21: =K21*(1+L55) -> 9346786.3
C22: Revenue from Component Repair | E22: 513416 | F22: 592422 | G22: 708560 | H22: =G22*(1+H60) -> 829015.2 | I22: =H22*(1+I60) -> 961657.63 | J22: =I22*(1+J60) -> 1110714.6 | K22: =J22*(1+K60) -> 1282875.3 | L22: =K22*(1+L60) -> 1475306.6
C23: Total Revenue | E23: =E22+E21 -> 4563284 | F23: =F22+F21 -> 5237161 | G23: =G22+G21 -> 6062512 | H23: =H22+H21 -> 6959290.2 | I23: =I22+I21 -> 7858217.1 | J23: =J22+J21 -> 8800378.3 | K23: =K22+K21 -> 9779953.8 | L23: =L22+L21 -> 10822093
C24: Cost of sales | E24: -3927965 | F24: -4483019 | G24: -5165060 | H24: =H25-H23 -> -5901478.1 | I24: =I25-I23 -> -6640193.4 | J24: =J25-J23 -> -7392317.8 | K24: =K25-K23 -> -8185821.3 | L24: =L25-L23 -> -9036447.6
C25: Gross Profit | E25: =SUM(E23:E24) -> 635319 | F25: =SUM(F23:F24) -> 754142 | G25: =SUM(G23:G24) -> 897452 | H25: =H23*H66 -> 1057812.1 | I25: =I23*I66 -> 1218023.6 | J25: =J23*J66 -> 1408060.5 | K25: =K23*K66 -> 1594132.5 | L25: =L23*L66 -> 1785645.3
C26: Amortisation of intangible assets | E26: -93681 | F26: -95457 | G26: -98681 | H26: =-H187*0.7516 -> -91261.527 | I26: =-I187*0.7516 -> -83538.837 | J26: =-J187*0.7516 -> -82367.092 | K26: =-K187*0.7516 -> -79979.259 | L26: =-L187*0.7516 -> -79200.602 | N26: Formula: Total Amortization from intangible Assets acc to note 9× 75% to excludes OEM auth amort which goes through COGS per Note 9.
C27: Selling, general & administrative | E27: -202766 | F27: -254092 | G27: -247703 | H27: =-H23*H71 -> -285330.9 | I27: =-I23*I71 -> -314328.68 | J27: =-J23*J71 -> -343214.75 | K27: =-K23*K71 -> -371638.24 | L27: =-L23*L71 -> -400417.44
C28: Acquisition Cost | E28: -1514 | F28: -1374 | G28: 0 | H28: =G28 -> 0 | I28: =H28 -> 0 | J28: =I28 -> 0 | K28: =J28 -> 0 | L28: =K28 -> 0
C29: Operating profit (EBIT) | E29: =SUM(E25:E28) -> 337358 | F29: =SUM(F25:F28) -> 403219 | G29: =SUM(G25:G28) -> 551068 | H29: =SUM(H25:H28) -> 681219.69 | I29: =SUM(I25:I28) -> 820156.12 | J29: =SUM(J25:J28) -> 982478.68 | K29: =SUM(K25:K28) -> 1142515 | L29: =SUM(L25:L28) -> 1306027.3
C30: Interest income | E30: 0 | F30: 0 | G30: 0 | H30: =H233 -> 0 | I30: =I233 -> 0 | J30: =J233 -> 0 | K30: =K233 -> 0 | L30: =L233 -> 0
C31: Interest expense | E31: -309645 | F31: -282507 | G31: -174217 | H31: =H219 -> -138781.63 | I31: =I219 -> -134154.66 | J31: =J219 -> -126377.68 | K31: =K219 -> -117025.71 | L31: =L219 -> -106098.74
C32: Refinancing costs | E32: -19921 | F32: -23700 | G32: 0 | H32: =G32 -> 0 | I32: =H32 -> 0 | J32: =I32 -> 0 | K32: =J32 -> 0 | L32: =K32 -> 0
C33: Loss on debt extinguishment | E33: -6182 | F33: -15255 | G33: 0 | H33: =G33 -> 0 | I33: =H33 -> 0 | J33: =I33 -> 0 | K33: =J33 -> 0 | L33: =K33 -> 0
C34: Other expense, net | E34: 3509 | F34: 0 | G34: 0 | H34: 0 | I34: 0 | J34: 0 | K34: 0 | L34: 0
C35: Pretax profit | E35: =SUM(E29:E34) -> 5119 | F35: =SUM(F29:F34) -> 81757 | G35: =SUM(G29:G34) -> 376851 | H35: =SUM(H29:H34) -> 542438.06 | I35: =SUM(I29:I34) -> 686001.47 | J35: =SUM(J29:J34) -> 856101 | K35: =SUM(K29:K34) -> 1025489.2 | L35: =SUM(L29:L34) -> 1199928.6
C36: Taxes | E36: -40180 | F36: -70783 | G36: -99435 | H36: =-H35*H76 -> -135609.52 | I36: =-I35*I76 -> -171500.37 | J36: =-J35*J76 -> -214025.25 | K36: =-K35*K76 -> -256372.31 | L36: =-L35*L76 -> -299982.14
C37: Net income | E37: =SUM(E35:E36) -> -35061 | F37: =SUM(F35:F36) -> 10974 | G37: =SUM(G35:G36) -> 277416 | H37: =SUM(H35:H36) -> 406828.55 | I37: =SUM(I35:I36) -> 514501.1 | J37: =SUM(J35:J36) -> 642075.75 | K37: =SUM(K35:K36) -> 769116.94 | L37: =SUM(L35:L36) -> 899946.41
C39: Depreciation & amortization | E39: 197104 | F39: 188164 | G39: 193664 | H39: =H189 -> 193053.33 | I39: =I189 -> 192030.77 | J39: =J189 -> 200169.21 | K39: =K189 -> 207074.75 | L39: =L189 -> 216765.24
C40: EBITDA | E40: =E29+E39 -> 534462 | F40: =F29+F39 -> 591383 | G40: =G29+G39 -> 744732 | H40: =H29+H39 -> 874273.02 | I40: =I29+I39 -> 1012186.9 | J40: =J29+J39 -> 1182647.9 | K40: =K29+K39 -> 1349589.7 | L40: =L29+L39 -> 1522792.5
C41: Stock based compensation | E41: - | F41: 17376 | G41: 13237 | H41: 13500 | I41: 14000 | J41: 14500 | K41: 15000 | L41: 15500
C42: Business transformation costs | E42: - | F42: 43239 | G42: 26028 | H42: - | I42: - | J42: - | K42: - | L42: -
C43: IPO related cost | E43: - | F43: 26909 | G43: 0 | H43: - | I43: - | J43: - | K43: - | L43: -
C44: Integration costs and severance | E44: - | F44: 2782 | G44: 5601 | H44: - | I44: - | J44: - | K44: - | L44: -
C45: Acquisition costs | E45: - | F45: 1374 | G45: 0 | H45: - | I45: - | J45: - | K45: - | L45: -
...

Sheet vF (2)
B2: X | C2: ="Financial Statement Model for "&D5 -> Financial Statement Model for StandardAero
C3: $ in thousands except per share
C5: Company name | D5: StandardAero
C6: Ticker | D6: SARO
D7: 1
C8: Latest closing share price | D8: 25.59
C9: Latest closing share price date | D9: 46119
C10: Latest fiscal year end date | D10: 46022
C11: Shares outstanding (millions) | D11: 334294 | M11: Outstanding at Dec 31, 2025 per 10-K BS. Jan 2026 repurchase of 1,637k shares (subsequent event) reduces to 332,657k.
B13: X | C13: INCOME STATEMENT
C14: Fiscal year | D14: =E14-1 -> 2023 | E14: =F14-1 -> 2024 | F14: =YEAR(D10) -> 2025 | G14: =F14+1 -> 2026 | H14: =G14+1 -> 2027 | I14: =H14+1 -> 2028 | J14: =I14+1 -> 2029 | K14: =J14+1 -> 2030
C15: Fiscal year end date | D15: =EOMONTH(E15,-12) -> 45291 | E15: =EOMONTH(F15,-12) -> 45657 | F15: =D10 -> 46022 | G15: =EOMONTH(F15,12) -> 46387 | H15: =EOMONTH(G15,12) -> 46752 | I15: =EOMONTH(H15,12) -> 47118 | J15: =EOMONTH(I15,12) -> 47483 | K15: =EOMONTH(J15,12) -> 47848 | M15: Comments
C17: Revenue from Engine Repair | D17: 4049868 | E17: 4644739 | F17: 5353952 | G17: =F17*(1+G50) -> 6130275 | H17: =G17*(1+H50) -> 6896559.4 | I17: =H17*(1+I50) -> 7689663.8 | J17: =I17*(1+J50) -> 8497078.4 | K17: =J17*(1+K50) -> 9346786.3
C18: Revenue from Component Repair | D18: 513416 | E18: 592422 | F18: 708560 | G18: =F18*(1+G51) -> 829015.2 | H18: =G18*(1+H51) -> 961657.63 | I18: =H18*(1+I51) -> 1110714.6 | J18: =I18*(1+J51) -> 1282875.3 | K18: =J18*(1+K51) -> 1475306.6
C19: Total Revenue | D19: =D18+D17 -> 4563284 | E19: =E18+E17 -> 5237161 | F19: =F18+F17 -> 6062512 | G19: =G18+G17 -> 6959290.2 | H19: =H18+H17 -> 7858217.1 | I19: =I18+I17 -> 8800378.3 | J19: =J18+J17 -> 9779953.8 | K19: =K18+K17 -> 10822093
C20: Cost of sales | D20: -3927965 | E20: -4483019 | F20: -5165060 | G20: =G21-G19 -> -5901478.1 | H20: =H21-H19 -> -6640193.4 | I20: =I21-I19 -> -7392317.8 | J20: =J21-J19 -> -8185821.3 | K20: =K21-K19 -> -9036447.6
C21: Gross Profit | D21: =SUM(D19:D20) -> 635319 | E21: =SUM(E19:E20) -> 754142 | F21: =SUM(F19:F20) -> 897452 | G21: =G19*G52 -> 1057812.1 | H21: =H19*H52 -> 1218023.6 | I21: =I19*I52 -> 1408060.5 | J21: =J19*J52 -> 1594132.5 | K21: =K19*K52 -> 1785645.3
C22: Amortisation of intangible assets | D22: -93681 | E22: -95457 | F22: -98681 | G22: =-G143*75% -> -91067.25 | H22: =-H143*75% -> -83361 | I22: =-I143*75% -> -82191.75 | J22: =-J143*75% -> -79809 | K22: =-K143*75% -> -79032 | M22: Formula: Total Amortization from intangible Assets acc to note 9× 75% to excludes OEM auth amort which goes through COGS per Note 9.
C23: Selling, general & administrative | D23: -202766 | E23: -254092 | F23: -247703 | G23: =-G19*G53 -> -285330.9 | H23: =-H19*H53 -> -314328.68 | I23: =-I19*I53 -> -343214.75 | J23: =-J19*J53 -> -371638.24 | K23: =-K19*K53 -> -400417.44
C24: Acquisition Cost | D24: -1514 | E24: -1374 | F24: 0 | G24: =F24 -> 0 | H24: =G24 -> 0 | I24: =H24 -> 0 | J24: =I24 -> 0 | K24: =J24 -> 0
C25: Operating profit (EBIT) | D25: =SUM(D21:D24) -> 337358 | E25: =SUM(E21:E24) -> 403219 | F25: =SUM(F21:F24) -> 551068 | G25: =SUM(G21:G24) -> 681413.97 | H25: =SUM(H21:H24) -> 820333.96 | I25: =SUM(I21:I24) -> 982654.03 | J25: =SUM(J21:J24) -> 1142685.2 | K25: =SUM(K21:K24) -> 1306195.9
C26: Interest income | D26: 0 | E26: 0 | F26: 0 | G26: =G189 -> 0 | H26: =H189 -> 0 | I26: =I189 -> 0 | J26: =J189 -> 0 | K26: =K189 -> 0
C27: Interest expense | D27: -309645 | E27: -282507 | F27: -174217 | G27: =G175 -> -138781.63 | H27: =H175 -> -134154.66 | I27: =I175 -> -126377.68 | J27: =J175 -> -117025.71 | K27: =K175 -> -106098.74
C28: Refinancing costs | D28: -19921 | E28: -23700 | F28: 0 | G28: =F28 -> 0 | H28: =G28 -> 0 | I28: =H28 -> 0 | J28: =I28 -> 0 | K28: =J28 -> 0
C29: Loss on debt extinguishment | D29: -6182 | E29: -15255 | F29: 0 | G29: =F29 -> 0 | H29: =G29 -> 0 | I29: =H29 -> 0 | J29: =I29 -> 0 | K29: =J29 -> 0
C30: Other expense, net | D30: 3509 | E30: 0 | F30: 0 | G30: 0 | H30: 0 | I30: 0 | J30: 0 | K30: 0
C31: Pretax profit | D31: =SUM(D25:D30) -> 5119 | E31: =SUM(E25:E30) -> 81757 | F31: =SUM(F25:F30) -> 376851 | G31: =SUM(G25:G30) -> 542632.34 | H31: =SUM(H25:H30) -> 686179.3 | I31: =SUM(I25:I30) -> 856276.34 | J31: =SUM(J25:J30) -> 1025659.5 | K31: =SUM(K25:K30) -> 1200097.2
C32: Taxes | D32: -40180 | E32: -70783 | F32: -99435 | G32: =-G31*G54 -> -135658.08 | H32: =-H31*H54 -> -171544.83 | I32: =-I31*I54 -> -214069.09 | J32: =-J31*J54 -> -256414.88 | K32: =-K31*K54 -> -300024.29
C33: Net income | D33: =SUM(D31:D32) -> -35061 | E33: =SUM(E31:E32) -> 10974 | F33: =SUM(F31:F32) -> 277416 | G33: =SUM(G31:G32) -> 406974.25 | H33: =SUM(H31:H32) -> 514634.48 | I33: =SUM(I31:I32) -> 642207.26 | J33: =SUM(J31:J32) -> 769244.63 | K33: =SUM(K31:K32) -> 900072.86
C35: Depreciation & amortization | D35: 197104 | E35: 188164 | F35: 193664 | G35: =G145 -> 193053.33 | H35: =H145 -> 192030.77 | I35: =I145 -> 200169.21 | J35: =J145 -> 207074.75 | K35: =K145 -> 216765.24
C36: EBITDA | D36: =D25+D35 -> 534462 | E36: =E25+E35 -> 591383 | F36: =F25+F35 -> 744732 | G36: =G25+G35 -> 874467.29 | H36: =H25+H35 -> 1012364.7 | I36: =I25+I35 -> 1182823.2 | J36: =J25+J35 -> 1349760 | K36: =K25+K35 -> 1522961.1
C37: Stock based compensation | E37: 17376 | F37: 13237
C38: Business transformation costs | E38: 43239 | F38: 26028
C39: IPO related cost | E39: 26909 | F39: 0
C40: Integration costs and severance | E40: 2782 | F40: 5601
C41: Acquisition costs | E41: 1374 | F41: 0
C42: Insureance recovery | E42: 0 | F42: -3000
C43: Loss on disposals | E43: 0 | F43: 2764
C44: Secondary offering costs | E44: 0 | F44: 4990
C45: Other | E45: 7470 | F45: 13820
...

Sheet Backup
B2: X | C2: ="Financial Statement Model for "&D5 -> Financial Statement Model for StandardAero
C3: $ in thousands except per share
C5: Company name | D5: StandardAero
C6: Ticker | D6: SARO
D7: 1
C8: Latest closing share price | D8: 25.59
C9: Latest closing share price date | D9: 46119
C10: Latest fiscal year end date | D10: 46022
C11: Shares outstanding (millions) | D11: 334294 | M11: Outstanding at Dec 31, 2025 per 10-K BS. Jan 2026 repurchase of 1,637k shares (subsequent event) reduces to 332,657k.
B13: X | C13: INCOME STATEMENT
C14: Fiscal year | D14: =E14-1 -> 2023 | E14: =F14-1 -> 2024 | F14: =YEAR(D10) -> 2025 | G14: =F14+1 -> 2026 | H14: =G14+1 -> 2027 | I14: =H14+1 -> 2028 | J14: =I14+1 -> 2029 | K14: =J14+1 -> 2030
C15: Fiscal year end date | D15: =EOMONTH(E15,-12) -> 45291 | E15: =EOMONTH(F15,-12) -> 45657 | F15: =D10 -> 46022 | G15: =EOMONTH(F15,12) -> 46387 | H15: =EOMONTH(G15,12) -> 46752 | I15: =EOMONTH(H15,12) -> 47118 | J15: =EOMONTH(I15,12) -> 47483 | K15: =EOMONTH(J15,12) -> 47848 | M15: Comments
C17: Revenue from Engine Repair | D17: 4049868 | E17: 4644739 | F17: 5353952 | G17: =F17*(1+G42) -> 6130275 | H17: =G17*(1+H42) -> 6896559.4 | I17: =H17*(1+I42) -> 7689663.8 | J17: =I17*(1+J42) -> 8497078.4 | K17: =J17*(1+K42) -> 9346786.3
C18: Revenue from Component Repair | D18: 513416 | E18: 592422 | F18: 708560 | G18: =F18*(1+G43) -> 829015.2 | H18: =G18*(1+H43) -> 961657.63 | I18: =H18*(1+I43) -> 1110714.6 | J18: =I18*(1+J43) -> 1282875.3 | K18: =J18*(1+K43) -> 1475306.6
C19: Total Revenue | D19: =D18+D17 -> 4563284 | E19: =E18+E17 -> 5237161 | F19: =F18+F17 -> 6062512 | G19: =G18+G17 -> 6959290.2 | H19: =H18+H17 -> 7858217.1 | I19: =I18+I17 -> 8800378.3 | J19: =J18+J17 -> 9779953.8 | K19: =K18+K17 -> 10822093
C20: Cost of sales | D20: -3927965 | E20: -4483019 | F20: -5165060 | G20: =G21-G19 -> -5901478.1 | H20: =H21-H19 -> -6640193.4 | I20: =I21-I19 -> -7392317.8 | J20: =J21-J19 -> -8185821.3 | K20: =K21-K19 -> -9036447.6
C21: Gross Profit | D21: =SUM(D19:D20) -> 635319 | E21: =SUM(E19:E20) -> 754142 | F21: =SUM(F19:F20) -> 897452 | G21: =G19*G44 -> 1057812.1 | H21: =H19*H44 -> 1218023.6 | I21: =I19*I44 -> 1408060.5 | J21: =J19*J44 -> 1594132.5 | K21: =K19*K44 -> 1785645.3
C22: Amortisation of intangible assets | D22: -93681 | E22: -95457 | F22: -98681 | G22: -91258 | H22: -84535 | I22: -85364 | J22: -84976 | K22: -87197 | M22: IS-line amort only (excl OEM auth amort in COGS). Total amort per Note 9 used for BS reduction in rows 62/63
C23: Selling, general & administrative | D23: -202766 | E23: -254092 | F23: -247703 | G23: =-G19*G45 -> -285330.9 | H23: =-H19*H45 -> -314328.68 | I23: =-I19*I45 -> -343214.75 | J23: =-J19*J45 -> -371638.24 | K23: =-K19*K45 -> -400417.44
C24: Acquisition Cost | D24: -1514 | E24: -1374 | F24: 0 | G24: =F24 -> 0 | H24: =G24 -> 0 | I24: =H24 -> 0 | J24: =I24 -> 0 | K24: =J24 -> 0
C25: Operating profit (EBIT) | D25: =SUM(D21:D24) -> 337358 | E25: =SUM(E21:E24) -> 403219 | F25: =SUM(F21:F24) -> 551068 | G25: =SUM(G21:G24) -> 681223.22 | H25: =SUM(H21:H24) -> 819159.96 | I25: =SUM(I21:I24) -> 979481.78 | J25: =SUM(J21:J24) -> 1137518.2 | K25: =SUM(K21:K24) -> 1298030.9
C26: Interest income | D26: 0 | E26: 0 | F26: 0 | G26: =G180 -> 0 | H26: =H180 -> 0 | I26: =I180 -> 0 | J26: =J180 -> 0 | K26: =K180 -> 0
C27: Interest expense | D27: -309645 | E27: -282507 | F27: -174217 | G27: =G166 -> -138781.63 | H27: =H166 -> -134154.66 | I27: =I166 -> -126377.68 | J27: =J166 -> -117025.71 | K27: =K166 -> -106098.74
C28: Refinancing costs | D28: -19921 | E28: -23700 | F28: 0 | G28: =F28 -> 0 | H28: =G28 -> 0 | I28: =H28 -> 0 | J28: =I28 -> 0 | K28: =J28 -> 0
C29: Loss on debt extinguishment | D29: -6182 | E29: -15255 | F29: 0 | G29: =F29 -> 0 | H29: =G29 -> 0 | I29: =H29 -> 0 | J29: =I29 -> 0 | K29: =J29 -> 0
C30: Other expense, net | D30: 3509 | E30: 0 | F30: 0 | G30: 0 | H30: 0 | I30: 0 | J30: 0 | K30: 0
C31: Pretax profit | D31: =SUM(D25:D30) -> 5119 | E31: =SUM(E25:E30) -> 81757 | F31: =SUM(F25:F30) -> 376851 | G31: =SUM(G25:G30) -> 542441.59 | H31: =SUM(H25:H30) -> 685005.3 | I31: =SUM(I25:I30) -> 853104.09 | J31: =SUM(J25:J30) -> 1020492.5 | K31: =SUM(K25:K30) -> 1191932.2
C32: Taxes | D32: -40180 | E32: -70783 | F32: -99435 | G32: =-G31*G46 -> -135610.4 | H32: =-H31*H46 -> -171251.33 | I32: =-I31*I46 -> -213276.02 | J32: =-J31*J46 -> -255123.13 | K32: =-K31*K46 -> -297983.04
C33: Net income | D33: =SUM(D31:D32) -> -35061 | E33: =SUM(E31:E32) -> 10974 | F33: =SUM(F31:F32) -> 277416 | G33: =SUM(G31:G32) -> 406831.19 | H33: =SUM(H31:H32) -> 513753.98 | I33: =SUM(I31:I32) -> 639828.07 | J33: =SUM(J31:J32) -> 765369.38 | K33: =SUM(K31:K32) -> 893949.11
C35: Depreciation & amortization | D35: 197104 | E35: 188164 | F35: 193664 | G35: =G136 -> 193053.33 | H35: =H136 -> 194030.77 | I35: =I136 -> 204169.21 | J35: =J136 -> 214074.75 | K35: =K136 -> 227765.24
C36: EBITDA | D36: =D25+D35 -> 534462 | E36: =E25+E35 -> 591383 | F36: =F25+F35 -> 744732 | G36: =G25+G35 -> 874276.54 | H36: =H25+H35 -> 1013190.7 | I36: =I25+I35 -> 1183651 | J36: =J25+J35 -> 1351593 | K36: =K25+K35 -> 1525796.1
C37: Stock based compensation | D37: 0 | E37: 17376 | F37: 13237 | G37: =F37 -> 13237 | H37: =G37 -> 13237 | I37: =H37 -> 13237 | J37: =I37 -> 13237 | K37: =J37 -> 13237
C40: Growth rates & margins
C41: Revenue growth | E41: =(E19-D19)/D19 -> 0.14767369 | F41: =(F19-E19)/E19 -> 0.15759512 | G41: =(G19-F19)/F19 -> 0.14792189 | H41: =(H19-G19)/G19 -> 0.12916932 | I41: =(I19-H19)/H19 -> 0.11989504 | J41: =(J19-I19)/I19 -> 0.11131061 | K41: =(K19-J19)/J19 -> 0.1065587 | M41: LEAP/CFM56 shop visits ramping; ~80% of revenue under long-term agreements; aging installed base drives MRO demand through 2030; military spending elevated due to geopolitical tensions; business aviation fleet growth
C42: Engine Service growth rate | E42: =(E17-D17)/D17 -> 0.14688652 | F42: =(F17-E17)/E17 -> 0.15269168 | G42: 0.145 | H42: 0.125 | I42: 0.115 | J42: 0.105 | K42: 0.1
C43: Component Repair Service growth rate | E43: =(E18-D18)/D18 -> 0.15388301 | F43: =(F18-E18)/E18 -> 0.19603931 | G43: 0.17 | H43: 0.16 | I43: 0.155 | J43: 0.155 | K43: 0.15
C44: Gross profit margin | D44: =D21/D19 -> 0.13922408 | E44: =E21/E19 -> 0.14399825 | F44: =F21/F19 -> 0.14803303 | G44: 0.152 | H44: 0.155 | I44: 0.16 | J44: 0.163 | K44: 0.165 | M44: LEAP learning curve progressively reduces industrialization costs; mix shift toward higher-margin Component Repair Services; operating leverage on fixed overhead as volumes scale; partially offset by material cost inflation pass-through
C45: SG&A % of sales | D45: =-D23/D19 -> 0.044434228 | E45: =-E23/E19 -> 0.048517126 | F45: =-F23/F19 -> 0.040858146 | G45: 0.041 | H45: 0.04 | I45: 0.039 | J45: 0.038 | K45: 0.037 | M45: SG&A already declined to 4.1% in 2025 (from 4.9% in 2024). Post-IPO one-time costs are behind the company. Further leverage expected as revenue scales against relatively fixed corporate overhead and sales force
C46: Tax rate | D46: =-D32/D31 -> 7.8491893 | E46: =-E32/E31 -> 0.86577296 | F46: =-F32/F31 -> 0.2638576 | G46: 0.25 | H46: 0.25 | I46: 0.25 | J46: 0.25 | K46: 0.25 | M46: 2025 effective rate of 26.4% includes GILTI, state taxes (California heavy), and changes in uncertain tax benefits. OBBBA provisions (signed Jul 4, 2025) restore favorable business tax treatment in 2026–2027 rate likely drifts toward 24–26% as Canada/foreign mix optimizes and interest carryforwards begin to release
B48: X | C48: BALANCE SHEET
...

Sheet vFixed
B2: X | C2: ="Financial Statement Model for "&D5 -> Financial Statement Model for StandardAero
C3: $ in thousands except per share
C5: Company name | D5: StandardAero
C6: Ticker | D6: SARO
D7: 1
C8: Latest closing share price | D8: 25.59
C9: Latest closing share price date | D9: 46119
C10: Latest fiscal year end date | D10: 46022
C11: Shares outstanding (millions) | D11: 334294 | M11: Outstanding at Dec 31, 2025 per 10-K BS. Jan 2026 repurchase of 1,637k shares (subsequent event) reduces to 332,657k.
B13: X | C13: INCOME STATEMENT
C14: Fiscal year | D14: =E14-1 -> 2023 | E14: =F14-1 -> 2024 | F14: =YEAR(D10) -> 2025 | G14: =F14+1 -> 2026 | H14: =G14+1 -> 2027 | I14: =H14+1 -> 2028 | J14: =I14+1 -> 2029 | K14: =J14+1 -> 2030
C15: Fiscal year end date | D15: =EOMONTH(E15,-12) -> 45291 | E15: =EOMONTH(F15,-12) -> 45657 | F15: =D10 -> 46022 | G15: =EOMONTH(F15,12) -> 46387 | H15: =EOMONTH(G15,12) -> 46752 | I15: =EOMONTH(H15,12) -> 47118 | J15: =EOMONTH(I15,12) -> 47483 | K15: =EOMONTH(J15,12) -> 47848 | M15: Comments
C17: Revenue from Engine Repair | D17: 4049868 | E17: 4644739 | F17: 5353952 | G17: =F17*(1+G42) -> 6130275 | H17: =G17*(1+H42) -> 6896559.4 | I17: =H17*(1+I42) -> 7689663.8 | J17: =I17*(1+J42) -> 8497078.4 | K17: =J17*(1+K42) -> 9346786.3
C18: Revenue from Component Repair | D18: 513416 | E18: 592422 | F18: 708560 | G18: =F18*(1+G43) -> 829015.2 | H18: =G18*(1+H43) -> 961657.63 | I18: =H18*(1+I43) -> 1110714.6 | J18: =I18*(1+J43) -> 1282875.3 | K18: =J18*(1+K43) -> 1475306.6
C19: Total Revenue | D19: =D18+D17 -> 4563284 | E19: =E18+E17 -> 5237161 | F19: =F18+F17 -> 6062512 | G19: =G18+G17 -> 6959290.2 | H19: =H18+H17 -> 7858217.1 | I19: =I18+I17 -> 8800378.3 | J19: =J18+J17 -> 9779953.8 | K19: =K18+K17 -> 10822093
C20: Cost of sales | D20: -3927965 | E20: -4483019 | F20: -5165060 | G20: =G21-G19 -> -5901478.1 | H20: =H21-H19 -> -6640193.4 | I20: =I21-I19 -> -7392317.8 | J20: =J21-J19 -> -8185821.3 | K20: =K21-K19 -> -9036447.6
C21: Gross Profit | D21: =SUM(D19:D20) -> 635319 | E21: =SUM(E19:E20) -> 754142 | F21: =SUM(F19:F20) -> 897452 | G21: =G19*G44 -> 1057812.1 | H21: =H19*H44 -> 1218023.6 | I21: =I19*I44 -> 1408060.5 | J21: =J19*J44 -> 1594132.5 | K21: =K19*K44 -> 1785645.3
C22: Amortisation of intangible assets | D22: -93681 | E22: -95457 | F22: -98681 | G22: -91258 | H22: -84535 | I22: -85364 | J22: -84976 | K22: -87197 | M22: IS-line amort only (excl OEM auth amort in COGS). Total amort per Note 9 used for BS reduction in rows 58/59.
C23: Selling, general & administrative | D23: -202766 | E23: -254092 | F23: -247703 | G23: =-G19*G45 -> -285330.9 | H23: =-H19*H45 -> -314328.68 | I23: =-I19*I45 -> -343214.75 | J23: =-J19*J45 -> -371638.24 | K23: =-K19*K45 -> -400417.44
C24: Acquisition Cost | D24: -1514 | E24: -1374 | F24: 0 | G24: =F24 -> 0 | H24: =G24 -> 0 | I24: =H24 -> 0 | J24: =I24 -> 0 | K24: =J24 -> 0
C25: Operating profit (EBIT) | D25: =SUM(D21:D24) -> 337358 | E25: =SUM(E21:E24) -> 403219 | F25: =SUM(F21:F24) -> 551068 | G25: =SUM(G21:G24) -> 681223.22 | H25: =SUM(H21:H24) -> 819159.96 | I25: =SUM(I21:I24) -> 979481.78 | J25: =SUM(J21:J24) -> 1137518.2 | K25: =SUM(K21:K24) -> 1298030.9
C26: Interest income | D26: 0 | E26: 0 | F26: 0 | G26: =G180 -> 0 | H26: =H180 -> 0 | I26: =I180 -> 0 | J26: =J180 -> 0 | K26: =K180 -> 0
C27: Interest expense | D27: -309645 | E27: -282507 | F27: -174217 | G27: =G166 -> -138781.63 | H27: =H166 -> -134154.66 | I27: =I166 -> -126377.68 | J27: =J166 -> -117025.71 | K27: =K166 -> -106098.74
C28: Refinancing costs | D28: -19921 | E28: -23700 | F28: 0 | G28: =F28 -> 0 | H28: =G28 -> 0 | I28: =H28 -> 0 | J28: =I28 -> 0 | K28: =J28 -> 0
C29: Loss on debt extinguishment | D29: -6182 | E29: -15255 | F29: 0 | G29: =F29 -> 0 | H29: =G29 -> 0 | I29: =H29 -> 0 | J29: =I29 -> 0 | K29: =J29 -> 0
C30: Other expense, net | D30: 3509 | E30: 0 | F30: 0 | G30: 0 | H30: 0 | I30: 0 | J30: 0 | K30: 0
C31: Pretax profit | D31: =SUM(D25:D30) -> 5119 | E31: =SUM(E25:E30) -> 81757 | F31: =SUM(F25:F30) -> 376851 | G31: =SUM(G25:G30) -> 542441.59 | H31: =SUM(H25:H30) -> 685005.3 | I31: =SUM(I25:I30) -> 853104.09 | J31: =SUM(J25:J30) -> 1020492.5 | K31: =SUM(K25:K30) -> 1191932.2
C32: Taxes | D32: -40180 | E32: -70783 | F32: -99435 | G32: =-G31*G46 -> -135610.4 | H32: =-H31*H46 -> -171251.33 | I32: =-I31*I46 -> -213276.02 | J32: =-J31*J46 -> -255123.13 | K32: =-K31*K46 -> -297983.04
C33: Net income | D33: =SUM(D31:D32) -> -35061 | E33: =SUM(E31:E32) -> 10974 | F33: =SUM(F31:F32) -> 277416 | G33: =SUM(G31:G32) -> 406831.19 | H33: =SUM(H31:H32) -> 513753.98 | I33: =SUM(I31:I32) -> 639828.07 | J33: =SUM(J31:J32) -> 765369.38 | K33: =SUM(K31:K32) -> 893949.11
C35: Depreciation & amortization | D35: 197104 | E35: 188164 | F35: 193664 | G35: =G136 -> 193053.33 | H35: =H136 -> 194030.77 | I35: =I136 -> 204169.21 | J35: =J136 -> 214074.75 | K35: =K136 -> 227765.24
C36: EBITDA | D36: =D25+D35 -> 534462 | E36: =E25+E35 -> 591383 | F36: =F25+F35 -> 744732 | G36: =G25+G35 -> 874276.54 | H36: =H25+H35 -> 1013190.7 | I36: =I25+I35 -> 1183651 | J36: =J25+J35 -> 1351593 | K36: =K25+K35 -> 1525796.1
C37: Stock based compensation | D37: 0 | E37: 17376 | F37: 13237 | G37: =F37 -> 13237 | H37: =G37 -> 13237 | I37: =H37 -> 13237 | J37: =I37 -> 13237 | K37: =J37 -> 13237
C38: Adjusted EBITDA | D38: =D36+D37 -> 534462 | E38: =E36+E37 -> 608759 | F38: =F36+F37 -> 757969 | G38: =G36+G37 -> 887513.54 | H38: =H36+H37 -> 1026427.7 | I38: =I36+I37 -> 1196888 | J38: =J36+J37 -> 1364830 | K38: =K36+K37 -> 1539033.1
C40: Growth rates & margins
C41: Revenue growth | E41: =(E19-D19)/D19 -> 0.14767369 | F41: =(F19-E19)/E19 -> 0.15759512 | G41: =(G19-F19)/F19 -> 0.14792189 | H41: =(H19-G19)/G19 -> 0.12916932 | I41: =(I19-H19)/H19 -> 0.11989504 | J41: =(J19-I19)/I19 -> 0.11131061 | K41: =(K19-J19)/J19 -> 0.1065587 | M41: LEAP/CFM56 shop visits ramping; ~80% of revenue under long-term agreements; aging installed base drives MRO demand through 2030; military spending elevated due to geopolitical tensions; business aviation fleet growth
C42: Engine Service growth rate | E42: =(E17-D17)/D17 -> 0.14688652 | F42: =(F17-E17)/E17 -> 0.15269168 | G42: 0.145 | H42: 0.125 | I42: 0.115 | J42: 0.105 | K42: 0.1
C43: Component Repair Service growth rate | E43: =(E18-D18)/D18 -> 0.15388301 | F43: =(F18-E18)/E18 -> 0.19603931 | G43: 0.17 | H43: 0.16 | I43: 0.155 | J43: 0.155 | K43: 0.15
C44: Gross profit margin | D44: =D21/D19 -> 0.13922408 | E44: =E21/E19 -> 0.14399825 | F44: =F21/F19 -> 0.14803303 | G44: 0.152 | H44: 0.155 | I44: 0.16 | J44: 0.163 | K44: 0.165 | M44: LEAP learning curve progressively reduces industrialization costs; mix shift toward higher-margin Component Repair Services; operating leverage on fixed overhead as volumes scale; partially offset by material cost inflation pass-through
C45: SG&A % of sales | D45: =-D23/D19 -> 0.044434228 | E45: =-E23/E19 -> 0.048517126 | F45: =-F23/F19 -> 0.040858146 | G45: 0.041 | H45: 0.04 | I45: 0.039 | J45: 0.038 | K45: 0.037 | M45: SG&A already declined to 4.1% in 2025 (from 4.9% in 2024). Post-IPO one-time costs are behind the company. Further leverage expected as revenue scales against relatively fixed corporate overhead and sales force
C46: Tax rate | D46: =-D32/D31 -> 7.8491893 | E46: =-E32/E31 -> 0.86577296 | F46: =-F32/F31 -> 0.2638576 | G46: 0.25 | H46: 0.25 | I46: 0.25 | J46: 0.25 | K46: 0.25 | M46: 2025 effective rate of 26.4% includes GILTI, state taxes (California heavy), and changes in uncertain tax benefits. OBBBA provisions (signed Jul 4, 2025) restore favorable business tax treatment in 2026–2027 rate likely drifts toward 24–26% as Canada/foreign mix optimizes and interest carryforwards begin to release
...

Sheet vF with M&A and Prepayment (2)
B2: X | C2: ="Financial Statement Model for "&D5 -> Financial Statement Model for StandardAero
C3: $ in thousands except per share
C5: Company name | D5: StandardAero
C6: Ticker | D6: SARO
D7: 1
C8: Latest closing share price | D8: 25.59
C9: Latest closing share price date | D9: 46119
C10: Latest fiscal year end date | D10: 46022
C11: Shares outstanding (millions) | D11: 334294 | M11: Outstanding at Dec 31, 2025 per 10-K BS. Jan 2026 repurchase of 1,637k shares (subsequent event) reduces to 332,657k.
B13: X | C13: INCOME STATEMENT
C14: Fiscal year | D14: =E14-1 -> 2023 | E14: =F14-1 -> 2024 | F14: =YEAR(D10) -> 2025 | G14: =F14+1 -> 2026 | H14: =G14+1 -> 2027 | I14: =H14+1 -> 2028 | J14: =I14+1 -> 2029 | K14: =J14+1 -> 2030
C15: Fiscal year end date | D15: =EOMONTH(E15,-12) -> 45291 | E15: =EOMONTH(F15,-12) -> 45657 | F15: =D10 -> 46022 | G15: =EOMONTH(F15,12) -> 46387 | H15: =EOMONTH(G15,12) -> 46752 | I15: =EOMONTH(H15,12) -> 47118 | J15: =EOMONTH(I15,12) -> 47483 | K15: =EOMONTH(J15,12) -> 47848 | M15: Comments
C17: Revenue from Engine Repair | D17: 4049868 | E17: 4644739 | F17: 5353952 | G17: =F17*(1+G42) -> 6130275 | H17: =G17*(1+H42) -> 6896559.4 | I17: =H17*(1+I42) -> 7689663.8 | J17: =I17*(1+J42) -> 8497078.4 | K17: =J17*(1+K42) -> 9346786.3
C18: Revenue from Component Repair | D18: 513416 | E18: 592422 | F18: 708560 | G18: =F18*(1+G43) -> 829015.2 | H18: =G18*(1+H43) -> 961657.63 | I18: =H18*(1+I43) -> 1110714.6 | J18: =I18*(1+J43) -> 1282875.3 | K18: =J18*(1+K43) -> 1475306.6
C19: Total Revenue | D19: =D18+D17 -> 4563284 | E19: =E18+E17 -> 5237161 | F19: =F18+F17 -> 6062512 | G19: =G18+G17 -> 6959290.2 | H19: =H18+H17 -> 7858217.1 | I19: =I18+I17 -> 8800378.3 | J19: =J18+J17 -> 9779953.8 | K19: =K18+K17 -> 10822093
C20: Cost of sales | D20: -3927965 | E20: -4483019 | F20: -5165060 | G20: =G21-G19 -> -5901478.1 | H20: =H21-H19 -> -6640193.4 | I20: =I21-I19 -> -7392317.8 | J20: =J21-J19 -> -8185821.3 | K20: =K21-K19 -> -9036447.6
C21: Gross Profit | D21: =SUM(D19:D20) -> 635319 | E21: =SUM(E19:E20) -> 754142 | F21: =SUM(F19:F20) -> 897452 | G21: =G19*G44 -> 1057812.1 | H21: =H19*H44 -> 1218023.6 | I21: =I19*I44 -> 1408060.5 | J21: =J19*J44 -> 1594132.5 | K21: =K19*K44 -> 1785645.3
C22: Amortisation of intangible assets | D22: -93681 | E22: -95457 | F22: -98681 | G22: -91258 | H22: -84535 | I22: -85364 | J22: -84976 | K22: -87197 | M22: IS-line amort only (excl OEM auth amort in COGS). Total amort per Note 9 used for BS reduction in rows 58/59.
C23: Selling, general & administrative | D23: -202766 | E23: -254092 | F23: -247703 | G23: =-G19*G45 -> -285330.9 | H23: =-H19*H45 -> -314328.68 | I23: =-I19*I45 -> -343214.75 | J23: =-J19*J45 -> -371638.24 | K23: =-K19*K45 -> -400417.44
C24: Acquisition Cost | D24: -1514 | E24: -1374 | F24: 0 | G24: =F24 -> 0 | H24: =G24 -> 0 | I24: =H24 -> 0 | J24: =I24 -> 0 | K24: =J24 -> 0
C25: Operating profit (EBIT) | D25: =SUM(D21:D24) -> 337358 | E25: =SUM(E21:E24) -> 403219 | F25: =SUM(F21:F24) -> 551068 | G25: =SUM(G21:G24) -> 681223.22 | H25: =SUM(H21:H24) -> 819159.96 | I25: =SUM(I21:I24) -> 979481.78 | J25: =SUM(J21:J24) -> 1137518.2 | K25: =SUM(K21:K24) -> 1298030.9
C26: Interest income | D26: 0 | E26: 0 | F26: 0 | G26: =G180 -> 0 | H26: =H180 -> 0 | I26: =I180 -> 0 | J26: =J180 -> 0 | K26: =K180 -> 0
C27: Interest expense | D27: -309645 | E27: -282507 | F27: -174217 | G27: =G166 -> -138781.63 | H27: =H166 -> -134154.66 | I27: =I166 -> -126377.68 | J27: =J166 -> -117025.71 | K27: =K166 -> -106098.74
C28: Refinancing costs | D28: -19921 | E28: -23700 | F28: 0 | G28: =F28 -> 0 | H28: =G28 -> 0 | I28: =H28 -> 0 | J28: =I28 -> 0 | K28: =J28 -> 0
C29: Loss on debt extinguishment | D29: -6182 | E29: -15255 | F29: 0 | G29: =F29 -> 0 | H29: =G29 -> 0 | I29: =H29 -> 0 | J29: =I29 -> 0 | K29: =J29 -> 0
C30: Other expense, net | D30: 3509 | E30: 0 | F30: 0 | G30: 0 | H30: 0 | I30: 0 | J30: 0 | K30: 0
C31: Pretax profit | D31: =SUM(D25:D30) -> 5119 | E31: =SUM(E25:E30) -> 81757 | F31: =SUM(F25:F30) -> 376851 | G31: =SUM(G25:G30) -> 542441.59 | H31: =SUM(H25:H30) -> 685005.3 | I31: =SUM(I25:I30) -> 853104.09 | J31: =SUM(J25:J30) -> 1020492.5 | K31: =SUM(K25:K30) -> 1191932.2
C32: Taxes | D32: -40180 | E32: -70783 | F32: -99435 | G32: =-G31*G46 -> -135610.4 | H32: =-H31*H46 -> -171251.33 | I32: =-I31*I46 -> -213276.02 | J32: =-J31*J46 -> -255123.13 | K32: =-K31*K46 -> -297983.04
C33: Net income | D33: =SUM(D31:D32) -> -35061 | E33: =SUM(E31:E32) -> 10974 | F33: =SUM(F31:F32) -> 277416 | G33: =SUM(G31:G32) -> 406831.19 | H33: =SUM(H31:H32) -> 513753.98 | I33: =SUM(I31:I32) -> 639828.07 | J33: =SUM(J31:J32) -> 765369.38 | K33: =SUM(K31:K32) -> 893949.11
C35: Depreciation & amortization | D35: 197104 | E35: 188164 | F35: 193664 | G35: =G136 -> 193053.33 | H35: =H136 -> 194030.77 | I35: =I136 -> 204169.21 | J35: =J136 -> 214074.75 | K35: =K136 -> 227765.24
C36: EBITDA | D36: =D25+D35 -> 534462 | E36: =E25+E35 -> 591383 | F36: =F25+F35 -> 744732 | G36: =G25+G35 -> 874276.54 | H36: =H25+H35 -> 1013190.7 | I36: =I25+I35 -> 1183651 | J36: =J25+J35 -> 1351593 | K36: =K25+K35 -> 1525796.1
C37: Stock based compensation | D37: 0 | E37: 17376 | F37: 13237 | G37: =F37 -> 13237 | H37: =G37 -> 13237 | I37: =H37 -> 13237 | J37: =I37 -> 13237 | K37: =J37 -> 13237
C38: Adjusted EBITDA | D38: =D36+D37 -> 534462 | E38: =E36+E37 -> 608759 | F38: =F36+F37 -> 757969 | G38: =G36+G37 -> 887513.54 | H38: =H36+H37 -> 1026427.7 | I38: =I36+I37 -> 1196888 | J38: =J36+J37 -> 1364830 | K38: =K36+K37 -> 1539033.1
C40: Growth rates & margins
C41: Revenue growth | E41: =(E19-D19)/D19 -> 0.14767369 | F41: =(F19-E19)/E19 -> 0.15759512 | G41: =(G19-F19)/F19 -> 0.14792189 | H41: =(H19-G19)/G19 -> 0.12916932 | I41: =(I19-H19)/H19 -> 0.11989504 | J41: =(J19-I19)/I19 -> 0.11131061 | K41: =(K19-J19)/J19 -> 0.1065587 | M41: LEAP/CFM56 shop visits ramping; ~80% of revenue under long-term agreements; aging installed base drives MRO demand through 2030; military spending elevated due to geopolitical tensions; business aviation fleet growth
C42: Engine Service growth rate | E42: =(E17-D17)/D17 -> 0.14688652 | F42: =(F17-E17)/E17 -> 0.15269168 | G42: 0.145 | H42: 0.125 | I42: 0.115 | J42: 0.105 | K42: 0.1
C43: Component Repair Service growth rate | E43: =(E18-D18)/D18 -> 0.15388301 | F43: =(F18-E18)/E18 -> 0.19603931 | G43: 0.17 | H43: 0.16 | I43: 0.155 | J43: 0.155 | K43: 0.15
C44: Gross profit margin | D44: =D21/D19 -> 0.13922408 | E44: =E21/E19 -> 0.14399825 | F44: =F21/F19 -> 0.14803303 | G44: 0.152 | H44: 0.155 | I44: 0.16 | J44: 0.163 | K44: 0.165 | M44: LEAP learning curve progressively reduces industrialization costs; mix shift toward higher-margin Component Repair Services; operating leverage on fixed overhead as volumes scale; partially offset by material cost inflation pass-through
C45: SG&A % of sales | D45: =-D23/D19 -> 0.044434228 | E45: =-E23/E19 -> 0.048517126 | F45: =-F23/F19 -> 0.040858146 | G45: 0.041 | H45: 0.04 | I45: 0.039 | J45: 0.038 | K45: 0.037 | M45: SG&A already declined to 4.1% in 2025 (from 4.9% in 2024). Post-IPO one-time costs are behind the company. Further leverage expected as revenue scales against relatively fixed corporate overhead and sales force
C46: Tax rate | D46: =-D32/D31 -> 7.8491893 | E46: =-E32/E31 -> 0.86577296 | F46: =-F32/F31 -> 0.2638576 | G46: 0.25 | H46: 0.25 | I46: 0.25 | J46: 0.25 | K46: 0.25 | M46: 2025 effective rate of 26.4% includes GILTI, state taxes (California heavy), and changes in uncertain tax benefits. OBBBA provisions (signed Jul 4, 2025) restore favorable business tax treatment in 2026–2027 rate likely drifts toward 24–26% as Canada/foreign mix optimizes and interest carryforwards begin to release
...

Sheet vF with M&A and Prepayment
B2: X | C2: ="Financial Statement Model for "&D5 -> Financial Statement Model for StandardAero
C3: $ in thousands except per share
C5: Company name | D5: StandardAero
C6: Ticker | D6: SARO
D7: 1
C8: Latest closing share price | D8: 25.59
C9: Latest closing share price date | D9: 46119
C10: Latest fiscal year end date | D10: 46022
C11: Shares outstanding (millions) | D11: 334294 | M11: Outstanding at Dec 31, 2025 per 10-K BS. Jan 2026 repurchase of 1,637k shares (subsequent event) reduces to 332,657k.
B13: X | C13: INCOME STATEMENT
C14: Fiscal year | D14: =E14-1 -> 2023 | E14: =F14-1 -> 2024 | F14: =YEAR(D10) -> 2025 | G14: =F14+1 -> 2026 | H14: =G14+1 -> 2027 | I14: =H14+1 -> 2028 | J14: =I14+1 -> 2029 | K14: =J14+1 -> 2030
C15: Fiscal year end date | D15: =EOMONTH(E15,-12) -> 45291 | E15: =EOMONTH(F15,-12) -> 45657 | F15: =D10 -> 46022 | G15: =EOMONTH(F15,12) -> 46387 | H15: =EOMONTH(G15,12) -> 46752 | I15: =EOMONTH(H15,12) -> 47118 | J15: =EOMONTH(I15,12) -> 47483 | K15: =EOMONTH(J15,12) -> 47848 | M15: Comments
C17: Revenue | D17: 4563284 | E17: 5237161 | F17: 6062513 | G17: =F17*(1+G39) -> 6971889.9 | H17: =G17*(1+H39) -> 7878235.6 | I17: =H17*(1+I39) -> 8823623.9 | J17: =I17*(1+J39) -> 9794222.6 | K17: =J17*(1+K39) -> 10773645
C18: Cost of sales | D18: -3927965 | E18: -4483019 | F18: -5165060 | G18: =G19-G17 -> -5912162.7 | H18: =H19-H17 -> -6657109.1 | I18: =I19-I17 -> -7411844.1 | J18: =J19-J17 -> -8197764.3 | K18: =K19-K17 -> -8995993.4
C19: Gross Profit | D19: =SUM(D17:D18) -> 635319 | E19: =SUM(E17:E18) -> 754142 | F19: =SUM(F17:F18) -> 897453 | G19: =G17*G40 -> 1059727.3 | H19: =H17*H40 -> 1221126.5 | I19: =I17*I40 -> 1411779.8 | J19: =J17*J40 -> 1596458.3 | K19: =K17*K40 -> 1777651.4
C20: Amortisation of intangible assets | D20: -93681 | E20: -95457 | F20: -98681 | G20: -91258 | H20: -84535 | I20: -85364 | J20: -84976 | K20: -87197 | M20: IS-line amort only (excl OEM auth amort in COGS). Total amort per Note 9 used for BS reduction in rows 58/59.
C21: Selling, general & administrative | D21: -202766 | E21: -254092 | F21: -247703 | G21: =-G17*G41 -> -285847.49 | H21: =-H17*H41 -> -315129.43 | I21: =-I17*I41 -> -344121.33 | J21: =-J17*J41 -> -372180.46 | K21: =-K17*K41 -> -398624.86
C22: Acquisition Cost | D22: -1514 | E22: -1374 | F22: 0 | G22: =F22 -> 0 | H22: =G22 -> 0 | I22: =H22 -> 0 | J22: =I22 -> 0 | K22: =J22 -> 0
C23: Operating profit (EBIT) | D23: =SUM(D19:D22) -> 337358 | E23: =SUM(E19:E22) -> 403219 | F23: =SUM(F19:F22) -> 551069 | G23: =SUM(G19:G22) -> 682621.78 | H23: =SUM(H19:H22) -> 821462.1 | I23: =SUM(I19:I22) -> 982294.49 | J23: =SUM(J19:J22) -> 1139301.8 | K23: =SUM(K19:K22) -> 1291829.5
C24: Interest income | D24: 0 | E24: 0 | F24: 0 | G24: =G176 -> 0 | H24: =H176 -> 0 | I24: =I176 -> 0 | J24: =J176 -> 0 | K24: =K176 -> 0
C25: Interest expense | D25: -309645 | E25: -282507 | F25: -174217 | G25: =G162 -> -138781.63 | H25: =H162 -> -134154.66 | I25: =I162 -> -126377.68 | J25: =J162 -> -117025.71 | K25: =K162 -> -106098.74
C26: Refinancing costs | D26: -19921 | E26: -23700 | F26: 0 | G26: =F26 -> 0 | H26: =G26 -> 0 | I26: =H26 -> 0 | J26: =I26 -> 0 | K26: =J26 -> 0
C27: Loss on debt extinguishment | D27: -6182 | E27: -15255 | F27: 0 | G27: =F27 -> 0 | H27: =G27 -> 0 | I27: =H27 -> 0 | J27: =I27 -> 0 | K27: =J27 -> 0
C28: Other expense, net | D28: 3509 | E28: 0 | F28: 0 | G28: 0 | H28: 0 | I28: 0 | J28: 0 | K28: 0
C29: Pretax profit | D29: =SUM(D23:D28) -> 5119 | E29: =SUM(E23:E28) -> 81757 | F29: =SUM(F23:F28) -> 376852 | G29: =SUM(G23:G28) -> 543840.16 | H29: =SUM(H23:H28) -> 687307.44 | I29: =SUM(I23:I28) -> 855916.81 | J29: =SUM(J23:J28) -> 1022276.1 | K29: =SUM(K23:K28) -> 1185730.8
C30: Taxes | D30: -40180 | E30: -70783 | F30: -99435 | G30: =-G29*G42 -> -135960.04 | H30: =-H29*H42 -> -171826.86 | I30: =-I29*I42 -> -213979.2 | J30: =-J29*J42 -> -255569.03 | K30: =-K29*K42 -> -296432.7
